Workbook

Sheet Sheet2
A1: ="اليوم: "&TEXT(TODAY(),"[$-060401]dddd، d mmmm yyyy")&" هـ | "&TEXT(TODAY(),"[$-ar-EG]dddd، d mmmm yyyy")&" م" -> اليوم: الثلاثاء، 3 ربيع الثاني 1448 هـ | الثلاثاء، 15 سبتمبر 2026 م
A2: # | B2: المهمة | C2: مسار إدارة المشروع | D2: كود المسار | E2: الوصف | F2: المسؤول | G2: الحالة | H2: تاريخ الرصد (هجري) | I2: تاريخ الاستحقاق (هجري) | J2: مصدر المهمة | K2: التحديث | L2: تاريخ الرصد (ميلادي) | M2: تاريخ الاستحقاق (ميلادي) | N2: فئة الاستحقاق | O2: توقف المهمة | P2: اجتماع الاحد | Q2: اجتماع الاربعاء
A3: 1 | B3: النموذج المعدني للتثبيت (عرفات) | C3: الحلول التقنية والتحقق الفني | D3: PM-03 | E3: رسم النموذج القياسي للهيكل (دعامات، عوارض، أبعاد، أحمال، جلفنة) وربط متطلباته بمتطلبات كدانة السابقة، ليُصنَّع مرة ويُكرَّر عند كل نقطة دخول | F3: أفاقي | G3: مكتمل | H3: 46250 | I3: 46274 | J3: الوزارة | K3: افاقى ارسلت على الجروب و الايميل ليتم التعميم على الشركات و الاعتماد كدانة و الدفاع المدني عن طريق الوزارة | L3: =IF($H3="","",TEXT($H3,"[$-ar-EG]dddd، d mmmm yyyy")) -> الأحد، 16 أغسطس 2026 | M3: =IF($I3="","",TEXT($I3,"[$-ar-EG]dddd، d mmmm yyyy")) -> الأربعاء، 9 سبتمبر 2026 | N3: {=IF(Table1[[#This Row],[المهمة]]="","",IF(TRIM(Table1[[#This Row],[الحالة]])="مكتمل","مكتملة",IF(Table1[[#This Row],[تاريخ الاستحقاق (هجري)]]="","بدون تاريخ",_xlfn.IFS(Table1[[#This Row],[تاريخ الاستحقاق (هجري)]]<TODAY(),"متأخرة",Table1[[#This Row],[تاريخ الاستحقاق (هجري)]]=TODAY(),"اليوم",Table1[[#This Row],[تاريخ الاستحقاق (هجري)]]=TODAY()+1,"غدًا",Table1[[#This Row],[تاريخ الاستحقاق (هجري)]]<=TODAY()-WEEKDAY(TODAY(),2)+7,"باقي هذا الأسبوع",Table1[[#This Row],[تاريخ الاستحقاق (هجري)]]<=TODAY()-WEEKDAY(TODAY(),2)+14,"الأسبوع القادم",Table1[[#This Row],[تاريخ الاستحقاق (هجري)]]<=EOMONTH(TODAY(),0),"باقي هذا الشهر",Table1[[#This Row],[تاريخ الاستحقاق (هجري)]]<=EOMONTH(TODAY(),1),"الشهر القادم",TRUE,"لاحقًا"))))} -> مكتملة
A4: 2 | B4: حساسات البيئة | C4: PM-04 | D4: PM-04 | E4: اعتماد نوع الأجهزة والحسسات التي سيتم التنفيذ بها بعد تقرير مهندس اياز | F4: الوزارة | G4: قيد الانتظار | H4: 46246 | I4: 46260 | J4: أفاقي | K4: في إنتظار الاعتماد بعد الاختبارفي الموقع الاخر وتقرير م اياز | L4: =IF($H4="","",TEXT($H4,"[$-ar-EG]dddd، d mmmm yyyy")) -> الأربعاء، 12 أغسطس 2026 | M4: =IF($I4="","",TEXT($I4,"[$-ar-EG]dddd، d mmmm yyyy")) -> الأربعاء، 26 أغسطس 2026 | N4: {=IF(Table1[[#This Row],[المهمة]]="","",IF(TRIM(Table1[[#This Row],[الحالة]])="مكتمل","مكتملة",IF(Table1[[#This Row],[تاريخ الاستحقاق (هجري)]]="","بدون تاريخ",_xlfn.IFS(Table1[[#This Row],[تاريخ الاستحقاق (هجري)]]<TODAY(),"متأخرة",Table1[[#This Row],[تاريخ الاستحقاق (هجري)]]=TODAY(),"اليوم",Table1[[#This Row],[تاريخ الاستحقاق (هجري)]]=TODAY()+1,"غدًا",Table1[[#This Row],[تاريخ الاستحقاق (هجري)]]<=TODAY()-WEEKDAY(TODAY(),2)+7,"باقي هذا الأسبوع",Table1[[#This Row],[تاريخ الاستحقاق (هجري)]]<=TODAY()-WEEKDAY(TODAY(),2)+14,"الأسبوع القادم",Table1[[#This Row],[تاريخ الاستحقاق (هجري)]]<=EOMONTH(TODAY(),0),"باقي هذا الشهر",Table1[[#This Row],[تاريخ الاستحقاق (هجري)]]<=EOMONTH(TODAY(),1),"الشهر القادم",TRUE,"لاحقًا"))))} -> متأخرة | Q4: التأكيد فى اجتماع الأحد
A5: 3 | B5: تركيب POC الحساسات بموقع ربوة منى | C5: التنفيذ والتشغيل الميداني | D5: PM-06 | E5: النزول فى الميدان مع المهندس اياز و تركيب ال POC فى مخيمات ربوة مني | F5: أفاقي | G5: مكتمل | H5: 46246 | I5: 46252 | J5: الوزارة | K5: تم التركيب | L5: =IF($H5="","",TEXT($H5,"[$-ar-EG]dddd، d mmmm yyyy")) -> الأربعاء، 12 أغسطس 2026 | M5: =IF($I5="","",TEXT($I5,"[$-ar-EG]dddd، d mmmm yyyy")) -> الثلاثاء، 18 أغسطس 2026 | N5: {=IF(Table1[[#This Row],[المهمة]]="","",IF(TRIM(Table1[[#This Row],[الحالة]])="مكتمل","مكتملة",IF(Table1[[#This Row],[تاريخ الاستحقاق (هجري)]]="","بدون تاريخ",_xlfn.IFS(Table1[[#This Row],[تاريخ الاستحقاق (هجري)]]<TODAY(),"متأخرة",Table1[[#This Row],[تاريخ الاستحقاق (هجري)]]=TODAY(),"اليوم",Table1[[#This Row],[تاريخ الاستحقاق (هجري)]]=TODAY()+1,"غدًا",Table1[[#This Row],[تاريخ الاستحقاق (هجري)]]<=TODAY()-WEEKDAY(TODAY(),2)+7,"باقي هذا الأسبوع",Table1[[#This Row],[تاريخ الاستحقاق (هجري)]]<=TODAY()-WEEKDAY(TODAY(),2)+14,"الأسبوع القادم",Table1[[#This Row],[تاريخ الاستحقاق (هجري)]]<=EOMONTH(TODAY(),0),"باقي هذا الشهر",Table1[[#This Row],[تاريخ الاستحقاق (هجري)]]<=EOMONTH(TODAY(),1),"الشهر القادم",TRUE,"لاحقًا"))))} -> مكتملة
A6: 4 | B6: النزول للمشاعر و استخراج التصاريح | C6: جاهزية المواقع والتنسيق الميداني | D6: PM-02 | E6: استخراج التصاريح لنزول الفرق الميدان و مراجعة كافة النقاط الخاصة بموسم 1448 | F6: أفاقي + الوزارة | G6: مكتمل | H6: 46246 | I6: 46266 | J6: الوزارة | K6: سيتم تحديد كافة المناطق بعد الاجتماع مع المهندس مجدى لعمل خطة مسح لكل الماطق والان يتم مناقشة عمل برنامج لتنسيق المسح لكافة النقاط و جدولتها بطريقة تسمح للوزارة بالمتابعة | L6: =IF($H6="","",TEXT($H6,"[$-ar-EG]dddd، d mmmm yyyy")) -> الأربعاء، 12 أغسطس 2026 | M6: =IF($I6="","",TEXT($I6,"[$-ar-EG]dddd، d mmmm yyyy")) -> الثلاثاء، 1 سبتمبر 2026 | N6: {=IF(Table1[[#This Row],[المهمة]]="","",IF(TRIM(Table1[[#This Row],[الحالة]])="مكتمل","مكتملة",IF(Table1[[#This Row],[تاريخ الاستحقاق (هجري)]]="","بدون تاريخ",_xlfn.IFS(Table1[[#This Row],[تاريخ الاستحقاق (هجري)]]<TODAY(),"متأخرة",Table1[[#This Row],[تاريخ الاستحقاق (هجري)]]=TODAY(),"اليوم",Table1[[#This Row],[تاريخ الاستحقاق (هجري)]]=TODAY()+1,"غدًا",Table1[[#This Row],[تاريخ الاستحقاق (هجري)]]<=TODAY()-WEEKDAY(TODAY(),2)+7,"باقي هذا الأسبوع",Table1[[#This Row],[تاريخ الاستحقاق (هجري)]]<=TODAY()-WEEKDAY(TODAY(),2)+14,"الأسبوع القادم",Table1[[#This Row],[تاريخ الاستحقاق (هجري)]]<=EOMONTH(TODAY(),0),"باقي هذا الشهر",Table1[[#This Row],[تاريخ الاستحقاق (هجري)]]<=EOMONTH(TODAY(),1),"الشهر القادم",TRUE,"لاحقًا"))))} -> مكتملة | Q6: تم البدء فى المسح الميدانى
A7: 5 | B7: المسح الميداني (كاميرات الوزارة) | C7: جاهزية المواقع والتنسيق الميداني | D7: PM-02 | E7: زيارة مواقع الكاميرات المثبتة التابعة للوزارة بمشعر منى والمواقع الأخرى وكذلك المواقع المستهدفة للتركيبات الجديدة | F7: الوزارة | G7: قيد الانتظار | H7: 46253 | I7: 46280 | J7: الوزارة | K7: بعد المراجعة والتدقيق، تم الرد على البريد وتوضيح البيانات المطلوبة لاستكمال تحديث الـ KMZ، وتشمل بيانات كاميرات LPR الـ17 بمواقع النوارية، بالإضافة إلى حدود ومواقع المناطق المطلوب تغطيتها في الزايدي ومركز الهجرة. بانتظار استلام البيانات | L7: =IF($H7="","",TEXT($H7,"[$-ar-EG]dddd، d mmmm yyyy")) -> الأربعاء، 19 أغسطس 2026 | M7: =IF($I7="","",TEXT($I7,"[$-ar-EG]dddd، d mmmm yyyy")) -> الثلاثاء، 15 سبتمبر 2026 | N7: {=IF(Table1[[#This Row],[المهمة]]="","",IF(TRIM(Table1[[#This Row],[الحالة]])="مكتمل","مكتملة",IF(Table1[[#This Row],[تاريخ الاستحقاق (هجري)]]="","بدون تاريخ",_xlfn.IFS(Table1[[#This Row],[تاريخ الاستحقاق (هجري)]]<TODAY(),"متأخرة",Table1[[#This Row],[تاريخ الاستحقاق (هجري)]]=TODAY(),"اليوم",Table1[[#This Row],[تاريخ الاستحقاق (هجري)]]=TODAY()+1,"غدًا",Table1[[#This Row],[تاريخ الاستحقاق (هجري)]]<=TODAY()-WEEKDAY(TODAY(),2)+7,"باقي هذا الأسبوع",Table1[[#This Row],[تاريخ الاستحقاق (هجري)]]<=TODAY()-WEEKDAY(TODAY(),2)+14,"الأسبوع القادم",Table1[[#This Row],[تاريخ الاستحقاق (هجري)]]<=EOMONTH(TODAY(),0),"باقي هذا الشهر",Table1[[#This Row],[تاريخ الاستحقاق (هجري)]]<=EOMONTH(TODAY(),1),"الشهر القادم",TRUE,"لاحقًا"))))} -> اليوم
A8: 6 | B8: المسح الميداني (قارئات) | C8: جاهزية المواقع والتنسيق الميداني | D8: PM-02 | E8: زيارة كل موقع لتحديد مستلزمات التركيب واعداد الأجهزة المطلوبة و رصد المواقع التي تتطلب مستلزمات خاصة في التركيب إن وجدت | F8: أفاقي | G8: قيد التنفيذ | H8: 46246 | I8: 46321 | J8: الوزارة | K8: تم بداية المسح الميداني بتاريخ 8-9-2026 | L8: =IF($H8="","",TEXT($H8,"[$-ar-EG]dddd، d mmmm yyyy")) -> الأربعاء، 12 أغسطس 2026 | M8: =IF($I8="","",TEXT($I8,"[$-ar-EG]dddd، d mmmm yyyy")) -> الإثنين، 26 أكتوبر 2026 | N8: {=IF(Table1[[#This Row],[المهمة]]="","",IF(TRIM(Table1[[#This Row],[الحالة]])="مكتمل","مكتملة",IF(Table1[[#This Row],[تاريخ الاستحقاق (هجري)]]="","بدون تاريخ",_xlfn.IFS(Table1[[#This Row],[تاريخ الاستحقاق (هجري)]]<TODAY(),"متأخرة",Table1[[#This Row],[تاريخ الاستحقاق (هجري)]]=TODAY(),"اليوم",Table1[[#This Row],[تاريخ الاستحقاق (هجري)]]=TODAY()+1,"غدًا",Table1[[#This Row],[تاريخ الاستحقاق (هجري)]]<=TODAY()-WEEKDAY(TODAY(),2)+7,"باقي هذا الأسبوع",Table1[[#This Row],[تاريخ الاستحقاق (هجري)]]<=TODAY()-WEEKDAY(TODAY(),2)+14,"الأسبوع القادم",Table1[[#This Row],[تاريخ الاستحقاق (هجري)]]<=EOMONTH(TODAY(),0),"باقي هذا الشهر",Table1[[#This Row],[تاريخ الاستحقاق (هجري)]]<=EOMONTH(TODAY(),1),"الشهر القادم",TRUE,"لاحقًا"))))} -> الشهر القادم
A9: 7 | B9: محاكاة بيئة منى مع المصانع | C9: الاعتماد الفني | D9: PM-04 | E9: التواصل مع المصانع لشرح بيئة العمل واهمية المشروع للوصول لافضل اداء باقل تكلفة | F9: أفاقي | G9: قيد الانتظار | H9: 46246 | I9: 46295 | J9: الوزارة | K9: جاري التنسيق لعقد اجتماعات مكثفة خلال الأسبوع القادم لشرح بيئة التشغيل ومتطلبات المشروع، بهدف تحديد Vendor قادر على تلبية المتطلبات | L9: =IF($H9="","",TEXT($H9,"[$-ar-EG]dddd، d mmmm yyyy")) -> الأربعاء، 12 أغسطس 2026 | M9: =IF($I9="","",TEXT($I9,"[$-ar-EG]dddd، d mmmm yyyy")) -> الأربعاء، 30 سبتمبر 2026 | N9: {=IF(Table1[[#This Row],[المهمة]]="","",IF(TRIM(Table1[[#This Row],[الحالة]])="مكتمل","مكتملة",IF(Table1[[#This Row],[تاريخ الاستحقاق (هجري)]]="","بدون تاريخ",_xlfn.IFS(Table1[[#This Row],[تاريخ الاستحقاق (هجري)]]<TODAY(),"متأخرة",Table1[[#This Row],[تاريخ الاستحقاق (هجري)]]=TODAY(),"اليوم",Table1[[#This Row],[تاريخ الاستحقاق (هجري)]]=TODAY()+1,"غدًا",Table1[[#This Row],[تاريخ الاستحقاق (هجري)]]<=TODAY()-WEEKDAY(TODAY(),2)+7,"باقي هذا الأسبوع",Table1[[#This Row],[تاريخ الاستحقاق (هجري)]]<=TODAY()-WEEKDAY(TODAY(),2)+14,"الأسبوع القادم",Table1[[#This Row],[تاريخ الاستحقاق (هجري)]]<=EOMONTH(TODAY(),0),"باقي هذا الشهر",Table1[[#This Row],[تاريخ الاستحقاق (هجري)]]<=EOMONTH(TODAY(),1),"الشهر القادم",TRUE,"لاحقًا"))))} -> باقي هذا الشهر | Q9: اجتماع الرياض الاسبوع القادم
A10: 8 | B10: تصنيع وتركيب الPOC للهيكل المعدني بعرفات | C10: الحلول التقنية والتحقق الفني | D10: PM-03 | E10: تنفيذ وتركيب الهيكل المعدني لاعتماده لدي كدانة والدفاع المدني والزام مزودي الخدمة بالتنفيذ | F10: أفاقي | G10: جاري العمل | H10: 46253 | I10: 46275 | J10: الوزارة | K10: تم التواصل جهة لتنفيذ الهيكل المعدني، وسيتم إبلاغكم بموعد التركيب فور الانتهاء من تجهيزه | L10: =IF($H10="","",TEXT($H10,"[$-ar-EG]dddd، d mmmm yyyy")) -> الأربعاء، 19 أغسطس 2026 | M10: =IF($I10="","",TEXT($I10,"[$-ar-EG]dddd، d mmmm yyyy")) -> الخميس، 10 سبتمبر 2026 | N10: {=IF(Table1[[#This Row],[المهمة]]="","",IF(TRIM(Table1[[#This Row],[الحالة]])="مكتمل","مكتملة",IF(Table1[[#This Row],[تاريخ الاستحقاق (هجري)]]="","بدون تاريخ",_xlfn.IFS(Table1[[#This Row],[تاريخ الاستحقاق (هجري)]]<TODAY(),"متأخرة",Table1[[#This Row],[تاريخ الاستحقاق (هجري)]]=TODAY(),"اليوم",Table1[[#This Row],[تاريخ الاستحقاق (هجري)]]=TODAY()+1,"غدًا",Table1[[#This Row],[تاريخ الاستحقاق (هجري)]]<=TODAY()-WEEKDAY(TODAY(),2)+7,"باقي هذا الأسبوع",Table1[[#This Row],[تاريخ الاستحقاق (هجري)]]<=TODAY()-WEEKDAY(TODAY(),2)+14,"الأسبوع القادم",Table1[[#This Row],[تاريخ الاستحقاق (هجري)]]<=EOMONTH(TODAY(),0),"باقي هذا الشهر",Table1[[#This Row],[تاريخ الاستحقاق (هجري)]]<=EOMONTH(TODAY(),1),"الشهر القادم",TRUE,"لاحقًا"))))} -> متأخرة | Q10: سيتم متابعته الاحد القادم
A11: 9 | B11: تأكيد وجود كهرباء مستمرة عند عمل POC فى مخيمات مني | C11: جاهزية المواقع والتنسيق الميداني | D11: PM-02 | E11: التأكيد ع وحود كهرباء لتوصيل حساسات البيئة | F11: الوزارة | G11: مكتمل | H11: 46251 | I11: 46253 | J11: أفاقي | K11: تم تحديد موقع ربوة منى لعمل التجارب و وجود كهرباء مستمرة بناء على افادة مهندس منشى | L11: =IF($H11="","",TEXT($H11,"[$-ar-EG]dddd، d mmmm yyyy")) -> الإثنين، 17 أغسطس 2026 | M11: =IF($I11="","",TEXT($I11,"[$-ar-EG]dddd، d mmmm yyyy")) -> الأربعاء، 19 أغسطس 2026 | N11: {=IF(Table1[[#This Row],[المهمة]]="","",IF(TRIM(Table1[[#This Row],[الحالة]])="مكتمل","مكتملة",IF(Table1[[#This Row],[تاريخ الاستحقاق (هجري)]]="","بدون تاريخ",_xlfn.IFS(Table1[[#This Row],[تاريخ الاستحقاق (هجري)]]<TODAY(),"متأخرة",Table1[[#This Row],[تاريخ الاستحقاق (هجري)]]=TODAY(),"اليوم",Table1[[#This Row],[تاريخ الاستحقاق (هجري)]]=TODAY()+1,"غدًا",Table1[[#This Row],[تاريخ الاستحقاق (هجري)]]<=TODAY()-WEEKDAY(TODAY(),2)+7,"باقي هذا الأسبوع",Table1[[#This Row],[تاريخ الاستحقاق (هجري)]]<=TODAY()-WEEKDAY(TODAY(),2)+14,"الأسبوع القادم",Table1[[#This Row],[تاريخ الاستحقاق (هجري)]]<=EOMONTH(TODAY(),0),"باقي هذا الشهر",Table1[[#This Row],[تاريخ الاستحقاق (هجري)]]<=EOMONTH(TODAY(),1),"الشهر القادم",TRUE,"لاحقًا"))))} -> مكتملة
A12: 10 | B12: تسليم عينة من منظومة قارئات نسك لإدارة التفويج (الدكتور وسام) | C12: الحلول التقنية والتحقق الفني | D12: PM-03 | E12: تسليم عيّنة تشغيلية متكاملة (قارئ + هوائيات + كاميرا عدّ + راوتر) للمعاينة الفنية وبناء القرار عليها. تم تجهيز المطلوب وفي انتظار تحديد موعد التسليم من إدارة التفويج | F12: أفاقي + إدارة التفويج | G12: مكتمل | H12: 46246 | I12: 46251 | J12: الوزارة | K12: تم تسليم العينة و الملفات الموضحة لكل المشروع بتغييراته بناء على توجيهاتكم | L12: =IF($H12="","",TEXT($H12,"[$-ar-EG]dddd، d mmmm yyyy")) -> الأربعاء، 12 أغسطس 2026 | M12: =IF($I12="","",TEXT($I12,"[$-ar-EG]dddd، d mmmm yyyy")) -> الإثنين، 17 أغسطس 2026 | N12: {=IF(Table1[[#This Row],[المهمة]]="","",IF(TRIM(Table1[[#This Row],[الحالة]])="مكتمل","مكتملة",IF(Table1[[#This Row],[تاريخ الاستحقاق (هجري)]]="","بدون تاريخ",_xlfn.IFS(Table1[[#This Row],[تاريخ الاستحقاق (هجري)]]<TODAY(),"متأخرة",Table1[[#This Row],[تاريخ الاستحقاق (هجري)]]=TODAY(),"اليوم",Table1[[#This Row],[تاريخ الاستحقاق (هجري)]]=TODAY()+1,"غدًا",Table1[[#This Row],[تاريخ الاستحقاق (هجري)]]<=TODAY()-WEEKDAY(TODAY(),2)+7,"باقي هذا الأسبوع",Table1[[#This Row],[تاريخ الاستحقاق (هجري)]]<=TODAY()-WEEKDAY(TODAY(),2)+14,"الأسبوع القادم",Table1[[#This Row],[تاريخ الاستحقاق (هجري)]]<=EOMONTH(TODAY(),0),"باقي هذا الشهر",Table1[[#This Row],[تاريخ الاستحقاق (هجري)]]<=EOMONTH(TODAY(),1),"الشهر القادم",TRUE,"لاحقًا"))))} -> مكتملة
A13: 11 | B13: ملف الأسئلة لمتابعة المهام بالاكشن بلان | C13: التخطيط والحوكمة | D13: PM-01 | E13: توحيد كل النقاط المفتوحة في مستند واحد، كملف مهام موحد يتم المتابعة عليه | F13: أفاقي + الوزارة | G13: مكتمل | H13: 46246 | I13: 46247 | J13: الوزارة | K13: يتم ارسال ملف المتابعة يوميا بكافة الملاحظات و التفاصيل المطلوبة لذا يرجى متابعته يوميا عند ارساله و ايفادنا بالملاحظات لحين الاجتماع | L13: =IF($H13="","",TEXT($H13,"[$-ar-EG]dddd، d mmmm yyyy")) -> الأربعاء، 12 أغسطس 2026 | M13: =IF($I13="","",TEXT($I13,"[$-ar-EG]dddd، d mmmm yyyy")) -> الخميس، 13 أغسطس 2026 | N13: {=IF(Table1[[#This Row],[المهمة]]="","",IF(TRIM(Table1[[#This Row],[الحالة]])="مكتمل","مكتملة",IF(Table1[[#This Row],[تاريخ الاستحقاق (هجري)]]="","بدون تاريخ",_xlfn.IFS(Table1[[#This Row],[تاريخ الاستحقاق (هجري)]]<TODAY(),"متأخرة",Table1[[#This Row],[تاريخ الاستحقاق (هجري)]]=TODAY(),"اليوم",Table1[[#This Row],[تاريخ الاستحقاق (هجري)]]=TODAY()+1,"غدًا",Table1[[#This Row],[تاريخ الاستحقاق (هجري)]]<=TODAY()-WEEKDAY(TODAY(),2)+7,"باقي هذا الأسبوع",Table1[[#This Row],[تاريخ الاستحقاق (هجري)]]<=TODAY()-WEEKDAY(TODAY(),2)+14,"الأسبوع القادم",Table1[[#This Row],[تاريخ الاستحقاق (هجري)]]<=EOMONTH(TODAY(),0),"باقي هذا الشهر",Table1[[#This Row],[تاريخ الاستحقاق (هجري)]]<=EOMONTH(TODAY(),1),"الشهر القادم",TRUE,"لاحقًا"))))} -> مكتملة
A14: 12 | B14: خطة العمل التفصيلية + خطة العمل الشهرية | C14: التخطيط والحوكمة | D14: PM-01 | E14: يتم دراسة عمل خطة كاملة مفصلة للمشروع مع توضيح نقاط الدعم المطلوبة | F14: أفاقي | G14: مكتمل | H14: 46370 | I14: 46253 | J14: الوزارة | K14: تم إعداد الخطة المبدئية وإرسالها للمناقشة، على أن يتم اعتماد تواريخها بناءً على موعد تخصيص المخيمات واعتماد كراسة الشروط | L14: =IF($H14="","",TEXT($H14,"[$-ar-EG]dddd، d mmmm yyyy")) -> الإثنين، 14 ديسمبر 2026 | M14: =IF($I14="","",TEXT($I14,"[$-ar-EG]dddd، d mmmm yyyy")) -> الأربعاء، 19 أغسطس 2026 | N14: {=IF(Table1[[#This Row],[المهمة]]="","",IF(TRIM(Table1[[#This Row],[الحالة]])="مكتمل","مكتملة",IF(Table1[[#This Row],[تاريخ الاستحقاق (هجري)]]="","بدون تاريخ",_xlfn.IFS(Table1[[#This Row],[تاريخ الاستحقاق (هجري)]]<TODAY(),"متأخرة",Table1[[#This Row],[تاريخ الاستحقاق (هجري)]]=TODAY(),"اليوم",Table1[[#This Row],[تاريخ الاستحقاق (هجري)]]=TODAY()+1,"غدًا",Table1[[#This Row],[تاريخ الاستحقاق (هجري)]]<=TODAY()-WEEKDAY(TODAY(),2)+7,"باقي هذا الأسبوع",Table1[[#This Row],[تاريخ الاستحقاق (هجري)]]<=TODAY()-WEEKDAY(TODAY(),2)+14,"الأسبوع القادم",Table1[[#This Row],[تاريخ الاستحقاق (هجري)]]<=EOMONTH(TODAY(),0),"باقي هذا الشهر",Table1[[#This Row],[تاريخ الاستحقاق (هجري)]]<=EOMONTH(TODAY(),1),"الشهر القادم",TRUE,"لاحقًا"))))} -> مكتملة
A15: 13 | B15: خطة العمل الشهرية | C15: التخطيط والحوكمة | D15: PM-01 | E15: يتم عمل خطة شهرية لاخر شهر اغسطس | F15: أفاقي | G15: مكتمل | H15: 46370 | I15: 46253 | J15: الوزارة | K15: تم إعداد الخطة المبدئية وإرسالها للمناقشة، على أن يتم اعتماد تواريخها بناءً على موعد تخصيص المخيمات واعتماد كراسة الشروط | L15: =IF($H15="","",TEXT($H15,"[$-ar-EG]dddd، d mmmm yyyy")) -> الإثنين، 14 ديسمبر 2026 | M15: =IF($I15="","",TEXT($I15,"[$-ar-EG]dddd، d mmmm yyyy")) -> الأربعاء، 19 أغسطس 2026 | N15: {=IF(Table1[[#This Row],[المهمة]]="","",IF(TRIM(Table1[[#This Row],[الحالة]])="مكتمل","مكتملة",IF(Table1[[#This Row],[تاريخ الاستحقاق (هجري)]]="","بدون تاريخ",_xlfn.IFS(Table1[[#This Row],[تاريخ الاستحقاق (هجري)]]<TODAY(),"متأخرة",Table1[[#This Row],[تاريخ الاستحقاق (هجري)]]=TODAY(),"اليوم",Table1[[#This Row],[تاريخ الاستحقاق (هجري)]]=TODAY()+1,"غدًا",Table1[[#This Row],[تاريخ الاستحقاق (هجري)]]<=TODAY()-WEEKDAY(TODAY(),2)+7,"باقي هذا الأسبوع",Table1[[#This Row],[تاريخ الاستحقاق (هجري)]]<=TODAY()-WEEKDAY(TODAY(),2)+14,"الأسبوع القادم",Table1[[#This Row],[تاريخ الاستحقاق (هجري)]]<=EOMONTH(TODAY(),0),"باقي هذا الشهر",Table1[[#This Row],[تاريخ الاستحقاق (هجري)]]<=EOMONTH(TODAY(),1),"الشهر القادم",TRUE,"لاحقًا"))))} -> مكتملة
A16: 14 | B16: تحليل السيناريوهات لموسم 1447 (تفصيل اليوزر كيس) | C16: الحلول التقنية والتحقق الفني | D16: PM-03 | E16: تم ارسال ملف بالدروس المستفادة متضمنة السيناريوهات المختلفة علي ارض الواقع وتأثيرها علي دقة البيانات بموسم 1447 | F16: أفاقي | G16: مكتمل | H16: 46246 | I16: 46247 | J16: الوزارة | K16: تم ارسال الملف من قبل و رجاء فتحه من هنا مرة اخري | L16: =IF($H16="","",TEXT($H16,"[$-ar-EG]dddd، d mmmm yyyy")) -> الأربعاء، 12 أغسطس 2026 | M16: =IF($I16="","",TEXT($I16,"[$-ar-EG]dddd، d mmmm yyyy")) -> الخميس، 13 أغسطس 2026 | N16: {=IF(Table1[[#This Row],[المهمة]]="","",IF(TRIM(Table1[[#This Row],[الحالة]])="مكتمل","مكتملة",IF(Table1[[#This Row],[تاريخ الاستحقاق (هجري)]]="","بدون تاريخ",_xlfn.IFS(Table1[[#This Row],[تاريخ الاستحقاق (هجري)]]<TODAY(),"متأخرة",Table1[[#This Row],[تاريخ الاستحقاق (هجري)]]=TODAY(),"اليوم",Table1[[#This Row],[تاريخ الاستحقاق (هجري)]]=TODAY()+1,"غدًا",Table1[[#This Row],[تاريخ الاستحقاق (هجري)]]<=TODAY()-WEEKDAY(TODAY(),2)+7,"باقي هذا الأسبوع",Table1[[#This Row],[تاريخ الاستحقاق (هجري)]]<=TODAY()-WEEKDAY(TODAY(),2)+14,"الأسبوع القادم",Table1[[#This Row],[تاريخ الاستحقاق (هجري)]]<=EOMONTH(TODAY(),0),"باقي هذا الشهر",Table1[[#This Row],[تاريخ الاستحقاق (هجري)]]<=EOMONTH(TODAY(),1),"الشهر القادم",TRUE,"لاحقًا"))))} -> مكتملة
A17: 15 | B17: نقل المنصة | C17: المنصة والبيانات والتكامل | D17: PM-05 | E17: تم تحديد البيئة المستهدفة وارسال البيانات المطلوبة لفريق علم مع أسماء المخولين بالولوج الي الخوادم بمركز معلومات الحج | F17: أفاقي | G17: قيد الانتظار | H17: 46246 | I17: 46260 | J17: الوزارة | K17: افادة مهندسي شركة علم تم الانتهاء من البنية التحتية والمستخدمين وفي انتظارارسال ميل بالتفاصيل المطلوبة | L17: =IF($H17="","",TEXT($H17,"[$-ar-EG]dddd، d mmmm yyyy")) -> الأربعاء، 12 أغسطس 2026 | M17: =IF($I17="","",TEXT($I17,"[$-ar-EG]dddd، d mmmm yyyy")) -> الأربعاء، 26 أغسطس 2026 | N17: {=IF(Table1[[#This Row],[المهمة]]="","",IF(TRIM(Table1[[#This Row],[الحالة]])="مكتمل","مكتملة",IF(Table1[[#This Row],[تاريخ الاستحقاق (هجري)]]="","بدون تاريخ",_xlfn.IFS(Table1[[#This Row],[تاريخ الاستحقاق (هجري)]]<TODAY(),"متأخرة",Table1[[#This Row],[تاريخ الاستحقاق (هجري)]]=TODAY(),"اليوم",Table1[[#This Row],[تاريخ الاستحقاق (هجري)]]=TODAY()+1,"غدًا",Table1[[#This Row],[تاريخ الاستحقاق (هجري)]]<=TODAY()-WEEKDAY(TODAY(),2)+7,"باقي هذا الأسبوع",Table1[[#This Row],[تاريخ الاستحقاق (هجري)]]<=TODAY()-WEEKDAY(TODAY(),2)+14,"الأسبوع القادم",Table1[[#This Row],[تاريخ الاستحقاق (هجري)]]<=EOMONTH(TODAY(),0),"باقي هذا الشهر",Table1[[#This Row],[تاريخ الاستحقاق (هجري)]]<=EOMONTH(TODAY(),1),"الشهر القادم",TRUE,"لاحقًا"))))} -> متأخرة | P17: سيتم بدء المراحل المتقدمة للنقل | Q17: متوقف عن افاقي في انتظار التحديث الاسبوع الثادم
A18: 16 | B18: نقل وتخزين تسجيلات كاميرات موسم 1447 مع الثيرد بارتى | C18: المنصة والبيانات والتكامل | D18: PM-05 | E18: تسليم التسجيلات المطلوبة للمراجعة الفنية للشركة المرشحة لهذه المهمة من قبل الوزارة | F18: الوزارة | G18: قيد الانتظار | H18: 46251 | I18: 46257 | J18: الوزارة | K18: سيتم عمل اجتماع اخرمع الثيرد بارتي | L18: =IF($H18="","",TEXT($H18,"[$-ar-EG]dddd، d mmmm yyyy")) -> الإثنين، 17 أغسطس 2026 | M18: =IF($I18="","",TEXT($I18,"[$-ar-EG]dddd، d mmmm yyyy")) -> الأحد، 23 أغسطس 2026 | N18: {=IF(Table1[[#This Row],[المهمة]]="","",IF(TRIM(Table1[[#This Row],[الحالة]])="مكتمل","مكتملة",IF(Table1[[#This Row],[تاريخ الاستحقاق (هجري)]]="","بدون تاريخ",_xlfn.IFS(Table1[[#This Row],[تاريخ الاستحقاق (هجري)]]<TODAY(),"متأخرة",Table1[[#This Row],[تاريخ الاستحقاق (هجري)]]=TODAY(),"اليوم",Table1[[#This Row],[تاريخ الاستحقاق (هجري)]]=TODAY()+1,"غدًا",Table1[[#This Row],[تاريخ الاستحقاق (هجري)]]<=TODAY()-WEEKDAY(TODAY(),2)+7,"باقي هذا الأسبوع",Table1[[#This Row],[تاريخ الاستحقاق (هجري)]]<=TODAY()-WEEKDAY(TODAY(),2)+14,"الأسبوع القادم",Table1[[#This Row],[تاريخ الاستحقاق (هجري)]]<=EOMONTH(TODAY(),0),"باقي هذا الشهر",Table1[[#This Row],[تاريخ الاستحقاق (هجري)]]<=EOMONTH(TODAY(),1),"الشهر القادم",TRUE,"لاحقًا"))))} -> متأخرة | P18: م مجدي
A19: 17 | B19: تحديد الدقة وتحسينها | C19: الحلول التقنية والتحقق الفني | D19: PM-03 | E19: تحسين قرائات القارئات والكاميرات الخاصة بالمنظومة لرفع دقة البيانات بموسم 1448 | F19: أفاقي | G19: قيد الانتظار | H19: 46246 | I19: 46326 | J19: الوزارة | K19: تم عمل تحديثات على كاميرات و قارئات لتحسين الكفاءة و الدقه و منها تجارب على ايجاد ال regional counting | L19: =IF($H19="","",TEXT($H19,"[$-ar-EG]dddd، d mmmm yyyy")) -> الأربعاء، 12 أغسطس 2026 | M19: =IF($I19="","",TEXT($I19,"[$-ar-EG]dddd، d mmmm yyyy")) -> السبت، 31 أكتوبر 2026 | N19: {=IF(Table1[[#This Row],[المهمة]]="","",IF(TRIM(Table1[[#This Row],[الحالة]])="مكتمل","مكتملة",IF(Table1[[#This Row],[تاريخ الاستحقاق (هجري)]]="","بدون تاريخ",_xlfn.IFS(Table1[[#This Row],[تاريخ الاستحقاق (هجري)]]<TODAY(),"متأخرة",Table1[[#This Row],[تاريخ الاستحقاق (هجري)]]=TODAY(),"اليوم",Table1[[#This Row],[تاريخ الاستحقاق (هجري)]]=TODAY()+1,"غدًا",Table1[[#This Row],[تاريخ الاستحقاق (هجري)]]<=TODAY()-WEEKDAY(TODAY(),2)+7,"باقي هذا الأسبوع",Table1[[#This Row],[تاريخ الاستحقاق (هجري)]]<=TODAY()-WEEKDAY(TODAY(),2)+14,"الأسبوع القادم",Table1[[#This Row],[تاريخ الاستحقاق (هجري)]]<=EOMONTH(TODAY(),0),"باقي هذا الشهر",Table1[[#This Row],[تاريخ الاستحقاق (هجري)]]<=EOMONTH(TODAY(),1),"الشهر القادم",TRUE,"لاحقًا"))))} -> الشهر القادم | P19: سيتم مشاركة تقرير فى اجتماع الاربعاء
A20: 18 | B20: جمع المتطلبات و تطوير المنصات | C20: المنصة والبيانات والتكامل | D20: PM-05 | E20: يتم عمل تصور مبدئي من افاقى لعرضه على الوزارة | F20: أفاقي | G20: مكتمل | H20: 46251 | I20: 46260 | J20: الوزارة | K20: تم اعداد ملف الدراسة الاستضاحية للمنصة وارساله | L20: =IF($H20="","",TEXT($H20,"[$-ar-EG]dddd، d mmmm yyyy")) -> الإثنين، 17 أغسطس 2026 | M20: =IF($I20="","",TEXT($I20,"[$-ar-EG]dddd، d mmmm yyyy")) -> الأربعاء، 26 أغسطس 2026 | N20: {=IF(Table1[[#This Row],[المهمة]]="","",IF(TRIM(Table1[[#This Row],[الحالة]])="مكتمل","مكتملة",IF(Table1[[#This Row],[تاريخ الاستحقاق (هجري)]]="","بدون تاريخ",_xlfn.IFS(Table1[[#This Row],[تاريخ الاستحقاق (هجري)]]<TODAY(),"متأخرة",Table1[[#This Row],[تاريخ الاستحقاق (هجري)]]=TODAY(),"اليوم",Table1[[#This Row],[تاريخ الاستحقاق (هجري)]]=TODAY()+1,"غدًا",Table1[[#This Row],[تاريخ الاستحقاق (هجري)]]<=TODAY()-WEEKDAY(TODAY(),2)+7,"باقي هذا الأسبوع",Table1[[#This Row],[تاريخ الاستحقاق (هجري)]]<=TODAY()-WEEKDAY(TODAY(),2)+14,"الأسبوع القادم",Table1[[#This Row],[تاريخ الاستحقاق (هجري)]]<=EOMONTH(TODAY(),0),"باقي هذا الشهر",Table1[[#This Row],[تاريخ الاستحقاق (هجري)]]<=EOMONTH(TODAY(),1),"الشهر القادم",TRUE,"لاحقًا"))))} -> مكتملة | P20: يوم الاربعاء | Q20: سيتم ارساله اليوم
A21: 19 | B21: عمل نظام داخلى لادارة المشروع كاملا | C21: التخطيط والحوكمة | D21: PM-01 | E21: مناقشة عمل نظام داخلى لادارة الزيارات و متابعة التركيبات | F21: أفاقي | G21: مكتمل | H21: 46251 | I21: 46265 | J21: أفاقي | K21: يتم مناقشة العمل على نظام داخلى ليغطى نطاق العمل بالكامل من اول زيارة الموقع حتى الانتهاء من التركيب و التسليم و الفك | L21: =IF($H21="","",TEXT($H21,"[$-ar-EG]dddd، d mmmm yyyy")) -> الإثنين، 17 أغسطس 2026 | M21: =IF($I21="","",TEXT($I21,"[$-ar-EG]dddd، d mmmm yyyy")) -> الإثنين، 31 أغسطس 2026 | N21: {=IF(Table1[[#This Row],[المهمة]]="","",IF(TRIM(Table1[[#This Row],[الحالة]])="مكتمل","مكتملة",IF(Table1[[#This Row],[تاريخ الاستحقاق (هجري)]]="","بدون تاريخ",_xlfn.IFS(Table1[[#This Row],[تاريخ الاستحقاق (هجري)]]<TODAY(),"متأخرة",Table1[[#This Row],[تاريخ الاستحقاق (هجري)]]=TODAY(),"اليوم",Table1[[#This Row],[تاريخ الاستحقاق (هجري)]]=TODAY()+1,"غدًا",Table1[[#This Row],[تاريخ الاستحقاق (هجري)]]<=TODAY()-WEEKDAY(TODAY(),2)+7,"باقي هذا الأسبوع",Table1[[#This Row],[تاريخ الاستحقاق (هجري)]]<=TODAY()-WEEKDAY(TODAY(),2)+14,"الأسبوع القادم",Table1[[#This Row],[تاريخ الاستحقاق (هجري)]]<=EOMONTH(TODAY(),0),"باقي هذا الشهر",Table1[[#This Row],[تاريخ الاستحقاق (هجري)]]<=EOMONTH(TODAY(),1),"الشهر القادم",TRUE,"لاحقًا"))))} -> مكتملة
A22: 20 | B22: ارسال بيانات ال vendor للحساسات | C22: الاعتماد الفني | D22: PM-04 | E22: ارسال اى vendor من الوزارة لتجربة اجهزته و عمل تقرير مفصل بالحالة التشغيلية | F22: الوزارة | G22: مكتمل | H22: 46251 | I22: 46253 | J22: الوزارة | K22: تم ارسال عرض السعر من ال vendor المقترح من الوزارة و سيتم التواصل معه خلال هذا الاسبوع | L22: =IF($H22="","",TEXT($H22,"[$-ar-EG]dddd، d mmmm yyyy")) -> الإثنين، 17 أغسطس 2026 | M22: =IF($I22="","",TEXT($I22,"[$-ar-EG]dddd، d mmmm yyyy")) -> الأربعاء، 19 أغسطس 2026 | N22: {=IF(Table1[[#This Row],[المهمة]]="","",IF(TRIM(Table1[[#This Row],[الحالة]])="مكتمل","مكتملة",IF(Table1[[#This Row],[تاريخ الاستحقاق (هجري)]]="","بدون تاريخ",_xlfn.IFS(Table1[[#This Row],[تاريخ الاستحقاق (هجري)]]<TODAY(),"متأخرة",Table1[[#This Row],[تاريخ الاستحقاق (هجري)]]=TODAY(),"اليوم",Table1[[#This Row],[تاريخ الاستحقاق (هجري)]]=TODAY()+1,"غدًا",Table1[[#This Row],[تاريخ الاستحقاق (هجري)]]<=TODAY()-WEEKDAY(TODAY(),2)+7,"باقي هذا الأسبوع",Table1[[#This Row],[تاريخ الاستحقاق (هجري)]]<=TODAY()-WEEKDAY(TODAY(),2)+14,"الأسبوع القادم",Table1[[#This Row],[تاريخ الاستحقاق (هجري)]]<=EOMONTH(TODAY(),0),"باقي هذا الشهر",Table1[[#This Row],[تاريخ الاستحقاق (هجري)]]<=EOMONTH(TODAY(),1),"الشهر القادم",TRUE,"لاحقًا"))))} -> مكتملة
A23: 21 | B23: بيانات الأبواب الرئيسية لمخيمات عرفات للموسم 1447 | C23: جاهزية المواقع والتنسيق الميداني | D23: PM-02 | E23: هل يوجد جداول تفويح و كيف يتم التفويج وتحديد ابواب الرئيسة للمخيمات بعرفات | F23: الوزارة | G23: مكتمل | H23: 46251 | I23: 46253 | J23: أفاقي | K23: تم ارسالها وجاري العمل عليها | L23: =IF($H23="","",TEXT($H23,"[$-ar-EG]dddd، d mmmm yyyy")) -> الإثنين، 17 أغسطس 2026 | M23: =IF($I23="","",TEXT($I23,"[$-ar-EG]dddd، d mmmm yyyy")) -> الأربعاء، 19 أغسطس 2026 | N23: {=IF(Table1[[#This Row],[المهمة]]="","",IF(TRIM(Table1[[#This Row],[الحالة]])="مكتمل","مكتملة",IF(Table1[[#This Row],[تاريخ الاستحقاق (هجري)]]="","بدون تاريخ",_xlfn.IFS(Table1[[#This Row],[تاريخ الاستحقاق (هجري)]]<TODAY(),"متأخرة",Table1[[#This Row],[تاريخ الاستحقاق (هجري)]]=TODAY(),"اليوم",Table1[[#This Row],[تاريخ الاستحقاق (هجري)]]=TODAY()+1,"غدًا",Table1[[#This Row],[تاريخ الاستحقاق (هجري)]]<=TODAY()-WEEKDAY(TODAY(),2)+7,"باقي هذا الأسبوع",Table1[[#This Row],[تاريخ الاستحقاق (هجري)]]<=TODAY()-WEEKDAY(TODAY(),2)+14,"الأسبوع القادم",Table1[[#This Row],[تاريخ الاستحقاق (هجري)]]<=EOMONTH(TODAY(),0),"باقي هذا الشهر",Table1[[#This Row],[تاريخ الاستحقاق (هجري)]]<=EOMONTH(TODAY(),1),"الشهر القادم",TRUE,"لاحقًا"))))} -> مكتملة | P23: يوم الاربعاء | Q23: سيتم مشاركة البيانت للموسم 1447
A24: 22 | B24: مواعيد تخصيص المخيمات للشركات | C24: جاهزية المواقع والتنسيق الميداني | D24: PM-02 | E24: تخصيص مخيمات منى و عرفات و تأكيد متطلبات العمل لتشغيل منظومة قارئات نسك قبل الموعد المحدد لكى يتم الانتهاء من المشروع فى الموعد المحدد | F24: الوزارة | G24: قيد الانتظار | H24: 46251 | I24: 46257 | J24: أفاقي | K24: فى انتظار الانتهاء ليتم عمل خطة كاملة تفصيلية | L24: =IF($H24="","",TEXT($H24,"[$-ar-EG]dddd، d mmmm yyyy")) -> الإثنين، 17 أغسطس 2026 | M24: =IF($I24="","",TEXT($I24,"[$-ar-EG]dddd، d mmmm yyyy")) -> الأحد، 23 أغسطس 2026 | N24: {=IF(Table1[[#This Row],[المهمة]]="","",IF(TRIM(Table1[[#This Row],[الحالة]])="مكتمل","مكتملة",IF(Table1[[#This Row],[تاريخ الاستحقاق (هجري)]]="","بدون تاريخ",_xlfn.IFS(Table1[[#This Row],[تاريخ الاستحقاق (هجري)]]<TODAY(),"متأخرة",Table1[[#This Row],[تاريخ الاستحقاق (هجري)]]=TODAY(),"اليوم",Table1[[#This Row],[تاريخ الاستحقاق (هجري)]]=TODAY()+1,"غدًا",Table1[[#This Row],[تاريخ الاستحقاق (هجري)]]<=TODAY()-WEEKDAY(TODAY(),2)+7,"باقي هذا الأسبوع",Table1[[#This Row],[تاريخ الاستحقاق (هجري)]]<=TODAY()-WEEKDAY(TODAY(),2)+14,"الأسبوع القادم",Table1[[#This Row],[تاريخ الاستحقاق (هجري)]]<=EOMONTH(TODAY(),0),"باقي هذا الشهر",Table1[[#This Row],[تاريخ الاستحقاق (هجري)]]<=EOMONTH(TODAY(),1),"الشهر القادم",TRUE,"لاحقًا"))))} -> متأخرة | Q24: سيتم التخصيص في شهر ذي القعدة
A25: 23 | B25: ارسال فريق للدوام من مبنى الوزارة | C25: التخطيط والحوكمة | D25: PM-01 | E25: ارسال ظباط الاتصال للعمل فى المشروع من مبنى الوزارة و الدوام كليا هناك | F25: أفاقي | G25: مكتمل | H25: 46246 | I25: 46266 | J25: الوزارة | L25: =IF($H25="","",TEXT($H25,"[$-ar-EG]dddd، d mmmm yyyy")) -> الأربعاء، 12 أغسطس 2026 | M25: =IF($I25="","",TEXT($I25,"[$-ar-EG]dddd، d mmmm yyyy")) -> الثلاثاء، 1 سبتمبر 2026 | N25: {=IF(Table1[[#This Row],[المهمة]]="","",IF(TRIM(Table1[[#This Row],[الحالة]])="مكتمل","مكتملة",IF(Table1[[#This Row],[تاريخ الاستحقاق (هجري)]]="","بدون تاريخ",_xlfn.IFS(Table1[[#This Row],[تاريخ الاستحقاق (هجري)]]<TODAY(),"متأخرة",Table1[[#This Row],[تاريخ الاستحقاق (هجري)]]=TODAY(),"اليوم",Table1[[#This Row],[تاريخ الاستحقاق (هجري)]]=TODAY()+1,"غدًا",Table1[[#This Row],[تاريخ الاستحقاق (هجري)]]<=TODAY()-WEEKDAY(TODAY(),2)+7,"باقي هذا الأسبوع",Table1[[#This Row],[تاريخ الاستحقاق (هجري)]]<=TODAY()-WEEKDAY(TODAY(),2)+14,"الأسبوع القادم",Table1[[#This Row],[تاريخ الاستحقاق (هجري)]]<=EOMONTH(TODAY(),0),"باقي هذا الشهر",Table1[[#This Row],[تاريخ الاستحقاق (هجري)]]<=EOMONTH(TODAY(),1),"الشهر القادم",TRUE,"لاحقًا"))))} -> مكتملة
A26: 24 | B26: اجتماع مع فريق كدانة لتحديد بعض النقاط فى مني و عرفات | C26: جاهزية المواقع والتنسيق الميداني | D26: PM-02 | E26: اجتماع مع كدانة لتحديد اماكن المظلات الموسم القادم مع امكانية العمل فى المخيمات بدون التخبط فى مشاريع اخري مثل مشروع اللوحات (نحو منى) | F26: أفاقي | G26: قيد الانتظار | H26: 46250 | I26: 46257 | J26: أفاقي | K26: سيتم عمل تقرير الاستشاري بعد الزيارة الميدانية للمواقع وتحديد نقاط الدعم المطلوبة من فريق كدانة | L26: =IF($H26="","",TEXT($H26,"[$-ar-EG]dddd، d mmmm yyyy")) -> الأحد، 16 أغسطس 2026 | M26: =IF($I26="","",TEXT($I26,"[$-ar-EG]dddd، d mmmm yyyy")) -> الأحد، 23 أغسطس 2026 | N26: {=IF(Table1[[#This Row],[المهمة]]="","",IF(TRIM(Table1[[#This Row],[الحالة]])="مكتمل","مكتملة",IF(Table1[[#This Row],[تاريخ الاستحقاق (هجري)]]="","بدون تاريخ",_xlfn.IFS(Table1[[#This Row],[تاريخ الاستحقاق (هجري)]]<TODAY(),"متأخرة",Table1[[#This Row],[تاريخ الاستحقاق (هجري)]]=TODAY(),"اليوم",Table1[[#This Row],[تاريخ الاستحقاق (هجري)]]=TODAY()+1,"غدًا",Table1[[#This Row],[تاريخ الاستحقاق (هجري)]]<=TODAY()-WEEKDAY(TODAY(),2)+7,"باقي هذا الأسبوع",Table1[[#This Row],[تاريخ الاستحقاق (هجري)]]<=TODAY()-WEEKDAY(TODAY(),2)+14,"الأسبوع القادم",Table1[[#This Row],[تاريخ الاستحقاق (هجري)]]<=EOMONTH(TODAY(),0),"باقي هذا الشهر",Table1[[#This Row],[تاريخ الاستحقاق (هجري)]]<=EOMONTH(TODAY(),1),"الشهر القادم",TRUE,"لاحقًا"))))} -> متأخرة | O26: واقف عند افاقي ( فريق المسح الميداني ) | P26: يتم عمل تقرير الاستشاري بعد الزيارة الميدانية | Q26: ٍيتم عمل اجتماع يوم الاربعاء القادم
A27: 25 | B27: تقسيم المهام الى مسارات | C27: التخطيط والحوكمة | D27: PM-01 | E27: تقسيم جميع المهام الى مسارات رئيسية | F27: أفاقي | G27: مكتمل | H27: 46257 | I27: 46258 | J27: الوزارة | K27: تم الانتهاء من تقسيم المسارات
A28: 26 | B28: ملف ال use casesالخاص بالتشغيل الفعلي | C28: الحلول التقنية والتحقق الفني | D28: PM-03 | E28: عمل ملف يوضح المشاكل الى اثرت على دقة قراءة البطاقات خلال التشغيل الفعلي | F28: أفاقي | G28: مكتمل | H28: 46257 | I28: 46258 | J28: الوزارة | K28: تم الارسال على مجموعة الواتس اب | L28: =IF($H28="","",TEXT($H28,"[$-ar-EG]dddd، d mmmm yyyy")) -> الأحد، 23 أغسطس 2026 | M28: =IF($I28="","",TEXT($I28,"[$-ar-EG]dddd، d mmmm yyyy")) -> الإثنين، 24 أغسطس 2026 | N28: {=IF(Table1[[#This Row],[المهمة]]="","",IF(TRIM(Table1[[#This Row],[الحالة]])="مكتمل","مكتملة",IF(Table1[[#This Row],[تاريخ الاستحقاق (هجري)]]="","بدون تاريخ",_xlfn.IFS(Table1[[#This Row],[تاريخ الاستحقاق (هجري)]]<TODAY(),"متأخرة",Table1[[#This Row],[تاريخ الاستحقاق (هجري)]]=TODAY(),"اليوم",Table1[[#This Row],[تاريخ الاستحقاق (هجري)]]=TODAY()+1,"غدًا",Table1[[#This Row],[تاريخ الاستحقاق (هجري)]]<=TODAY()-WEEKDAY(TODAY(),2)+7,"باقي هذا الأسبوع",Table1[[#This Row],[تاريخ الاستحقاق (هجري)]]<=TODAY()-WEEKDAY(TODAY(),2)+14,"الأسبوع القادم",Table1[[#This Row],[تاريخ الاستحقاق (هجري)]]<=EOMONTH(TODAY(),0),"باقي هذا الشهر",Table1[[#This Row],[تاريخ الاستحقاق (هجري)]]<=EOMONTH(TODAY(),1),"الشهر القادم",TRUE,"لاحقًا"))))} -> مكتملة | P28: غدا
A29: 27 | B29: اعادة تركيب الحساسات بموقع اخر | C29: التنفيذ والتشغيل الميداني | D29: PM-06 | E29: اعادة التركيب فى مخيم اخر لمقارنة البيانات بالتنسيق مع مهندس اياز | F29: أفاقي | G29: قيد الانتظار | H29: 46257 | I29: 46261 | J29: الوزارة | K29: في انتظارتصريح الدخول والأعمال الميدانية وتحديد المخيم المراد و رقم التواصل مع ظابط الاتصال ان وجد | L29: =IF($H29="","",TEXT($H29,"[$-ar-EG]dddd، d mmmm yyyy")) -> الأحد، 23 أغسطس 2026 | M29: =IF($I29="","",TEXT($I29,"[$-ar-EG]dddd، d mmmm yyyy")) -> الخميس، 27 أغسطس 2026 | N29: {=IF(Table1[[#This Row],[المهمة]]="","",IF(TRIM(Table1[[#This Row],[الحالة]])="مكتمل","مكتملة",IF(Table1[[#This Row],[تاريخ الاستحقاق (هجري)]]="","بدون تاريخ",_xlfn.IFS(Table1[[#This Row],[تاريخ الاستحقاق (هجري)]]<TODAY(),"متأخرة",Table1[[#This Row],[تاريخ الاستحقاق (هجري)]]=TODAY(),"اليوم",Table1[[#This Row],[تاريخ الاستحقاق (هجري)]]=TODAY()+1,"غدًا",Table1[[#This Row],[تاريخ الاستحقاق (هجري)]]<=TODAY()-WEEKDAY(TODAY(),2)+7,"باقي هذا الأسبوع",Table1[[#This Row],[تاريخ الاستحقاق (هجري)]]<=TODAY()-WEEKDAY(TODAY(),2)+14,"الأسبوع القادم",Table1[[#This Row],[تاريخ الاستحقاق (هجري)]]<=EOMONTH(TODAY(),0),"باقي هذا الشهر",Table1[[#This Row],[تاريخ الاستحقاق (هجري)]]<=EOMONTH(TODAY(),1),"الشهر القادم",TRUE,"لاحقًا"))))} -> متأخرة | P29: خلال الاسبوع | Q29: النزول يوم الاحد مع المهندس اياز
A30: 28 | B30: ملف use cases الخاص بالمنصة وكيفية معالجتها | C30: الحلول التقنية والتحقق الفني | D30: PM-03 | E30: عمل ملف يوضح المشاكل الى اثرت على دقة قراءة البطاقات من النظام | F30: أفاقي | G30: مكتمل | H30: 46257 | I30: 46258 | J30: الوزارة | K30: تم الإرسال على مجموعة الواتس اب | L30: =IF($H30="","",TEXT($H30,"[$-ar-EG]dddd، d mmmm yyyy")) -> الأحد، 23 أغسطس 2026 | M30: =IF($I30="","",TEXT($I30,"[$-ar-EG]dddd، d mmmm yyyy")) -> الإثنين، 24 أغسطس 2026 | N30: {=IF(Table1[[#This Row],[المهمة]]="","",IF(TRIM(Table1[[#This Row],[الحالة]])="مكتمل","مكتملة",IF(Table1[[#This Row],[تاريخ الاستحقاق (هجري)]]="","بدون تاريخ",_xlfn.IFS(Table1[[#This Row],[تاريخ الاستحقاق (هجري)]]<TODAY(),"متأخرة",Table1[[#This Row],[تاريخ الاستحقاق (هجري)]]=TODAY(),"اليوم",Table1[[#This Row],[تاريخ الاستحقاق (هجري)]]=TODAY()+1,"غدًا",Table1[[#This Row],[تاريخ الاستحقاق (هجري)]]<=TODAY()-WEEKDAY(TODAY(),2)+7,"باقي هذا الأسبوع",Table1[[#This Row],[تاريخ الاستحقاق (هجري)]]<=TODAY()-WEEKDAY(TODAY(),2)+14,"الأسبوع القادم",Table1[[#This Row],[تاريخ الاستحقاق (هجري)]]<=EOMONTH(TODAY(),0),"باقي هذا الشهر",Table1[[#This Row],[تاريخ الاستحقاق (هجري)]]<=EOMONTH(TODAY(),1),"الشهر القادم",TRUE,"لاحقًا"))))} -> مكتملة | Q30: سيتم ارسال اليوم
A31: 29 | B31: خطة تفصيلية بملف اكسل من الوزارة | C31: التخطيط والحوكمة | D31: PM-01 | E31: مشاركة ملف اكسل بالخطة بناء على template الوزارة | F31: الوزارة | G31: مكتمل | H31: 46257 | I31: 46258 | J31: الوزارة | L31: =IF($H31="","",TEXT($H31,"[$-ar-EG]dddd، d mmmm yyyy")) -> الأحد، 23 أغسطس 2026 | M31: =IF($I31="","",TEXT($I31,"[$-ar-EG]dddd، d mmmm yyyy")) -> الإثنين، 24 أغسطس 2026 | N31: {=IF(Table1[[#This Row],[المهمة]]="","",IF(TRIM(Table1[[#This Row],[الحالة]])="مكتمل","مكتملة",IF(Table1[[#This Row],[تاريخ الاستحقاق (هجري)]]="","بدون تاريخ",_xlfn.IFS(Table1[[#This Row],[تاريخ الاستحقاق (هجري)]]<TODAY(),"متأخرة",Table1[[#This Row],[تاريخ الاستحقاق (هجري)]]=TODAY(),"اليوم",Table1[[#This Row],[تاريخ الاستحقاق (هجري)]]=TODAY()+1,"غدًا",Table1[[#This Row],[تاريخ الاستحقاق (هجري)]]<=TODAY()-WEEKDAY(TODAY(),2)+7,"باقي هذا الأسبوع",Table1[[#This Row],[تاريخ الاستحقاق (هجري)]]<=TODAY()-WEEKDAY(TODAY(),2)+14,"الأسبوع القادم",Table1[[#This Row],[تاريخ الاستحقاق (هجري)]]<=EOMONTH(TODAY(),0),"باقي هذا الشهر",Table1[[#This Row],[تاريخ الاستحقاق (هجري)]]<=EOMONTH(TODAY(),1),"الشهر القادم",TRUE,"لاحقًا"))))} -> مكتملة | Q31: مكتمل
A32: 30 | B32: خطة تفصيلية بملف اكسل من افاقى | C32: التخطيط والحوكمة | D32: PM-01 | E32: مشاركة ملف مبدئى من افاقى | F32: أفاقي | G32: مكتمل | H32: 46257 | I32: 46258 | J32: الوزارة | L32: =IF($H32="","",TEXT($H32,"[$-ar-EG]dddd، d mmmm yyyy")) -> الأحد، 23 أغسطس 2026 | M32: =IF($I32="","",TEXT($I32,"[$-ar-EG]dddd، d mmmm yyyy")) -> الإثنين، 24 أغسطس 2026 | N32: {=IF(Table1[[#This Row],[المهمة]]="","",IF(TRIM(Table1[[#This Row],[الحالة]])="مكتمل","مكتملة",IF(Table1[[#This Row],[تاريخ الاستحقاق (هجري)]]="","بدون تاريخ",_xlfn.IFS(Table1[[#This Row],[تاريخ الاستحقاق (هجري)]]<TODAY(),"متأخرة",Table1[[#This Row],[تاريخ الاستحقاق (هجري)]]=TODAY(),"اليوم",Table1[[#This Row],[تاريخ الاستحقاق (هجري)]]=TODAY()+1,"غدًا",Table1[[#This Row],[تاريخ الاستحقاق (هجري)]]<=TODAY()-WEEKDAY(TODAY(),2)+7,"باقي هذا الأسبوع",Table1[[#This Row],[تاريخ الاستحقاق (هجري)]]<=TODAY()-WEEKDAY(TODAY(),2)+14,"الأسبوع القادم",Table1[[#This Row],[تاريخ الاستحقاق (هجري)]]<=EOMONTH(TODAY(),0),"باقي هذا الشهر",Table1[[#This Row],[تاريخ الاستحقاق (هجري)]]<=EOMONTH(TODAY(),1),"الشهر القادم",TRUE,"لاحقًا"))))} -> مكتملة | Q32: مكتمل
A33: 31 | B33: النموذج الإبداعي الخاص بالقارئات | C33: التخطيط والحوكمة | D33: PM-01 | E33: الرد على ايميل النموذج الإبداعي الخاص بالقارئات | F33: أفاقي | G33: مكتمل | H33: 46259 | I33: 46260 | J33: الوزارة | K33: تم ارسال على جروب الواتس اب | L33: =IF($H33="","",TEXT($H33,"[$-ar-EG]dddd، d mmmm yyyy")) -> الثلاثاء، 25 أغسطس 2026 | M33: =IF($I33="","",TEXT($I33,"[$-ar-EG]dddd، d mmmm yyyy")) -> الأربعاء، 26 أغسطس 2026 | N33: {=IF(Table1[[#This Row],[المهمة]]="","",IF(TRIM(Table1[[#This Row],[الحالة]])="مكتمل","مكتملة",IF(Table1[[#This Row],[تاريخ الاستحقاق (هجري)]]="","بدون تاريخ",_xlfn.IFS(Table1[[#This Row],[تاريخ الاستحقاق (هجري)]]<TODAY(),"متأخرة",Table1[[#This Row],[تاريخ الاستحقاق (هجري)]]=TODAY(),"اليوم",Table1[[#This Row],[تاريخ الاستحقاق (هجري)]]=TODAY()+1,"غدًا",Table1[[#This Row],[تاريخ الاستحقاق (هجري)]]<=TODAY()-WEEKDAY(TODAY(),2)+7,"باقي هذا الأسبوع",Table1[[#This Row],[تاريخ الاستحقاق (هجري)]]<=TODAY()-WEEKDAY(TODAY(),2)+14,"الأسبوع القادم",Table1[[#This Row],[تاريخ الاستحقاق (هجري)]]<=EOMONTH(TODAY(),0),"باقي هذا الشهر",Table1[[#This Row],[تاريخ الاستحقاق (هجري)]]<=EOMONTH(TODAY(),1),"الشهر القادم",TRUE,"لاحقًا"))))} -> مكتملة
A34: 32 | B34: الشواهد والمتطلبات المطلوبة | C34: التخطيط والحوكمة | D34: PM-01 | E34: الرد على ايميل الشواهد والمتطلبات المطلوبة | F34: أفاقي | G34: مكتمل | H34: 46259 | I34: 46260 | J34: الوزارة | K34: تم ارسال على جروب الواتس اب | L34: =IF($H34="","",TEXT($H34,"[$-ar-EG]dddd، d mmmm yyyy")) -> الثلاثاء، 25 أغسطس 2026 | M34: =IF($I34="","",TEXT($I34,"[$-ar-EG]dddd، d mmmm yyyy")) -> الأربعاء، 26 أغسطس 2026 | N34: {=IF(Table1[[#This Row],[المهمة]]="","",IF(TRIM(Table1[[#This Row],[الحالة]])="مكتمل","مكتملة",IF(Table1[[#This Row],[تاريخ الاستحقاق (هجري)]]="","بدون تاريخ",_xlfn.IFS(Table1[[#This Row],[تاريخ الاستحقاق (هجري)]]<TODAY(),"متأخرة",Table1[[#This Row],[تاريخ الاستحقاق (هجري)]]=TODAY(),"اليوم",Table1[[#This Row],[تاريخ الاستحقاق (هجري)]]=TODAY()+1,"غدًا",Table1[[#This Row],[تاريخ الاستحقاق (هجري)]]<=TODAY()-WEEKDAY(TODAY(),2)+7,"باقي هذا الأسبوع",Table1[[#This Row],[تاريخ الاستحقاق (هجري)]]<=TODAY()-WEEKDAY(TODAY(),2)+14,"الأسبوع القادم",Table1[[#This Row],[تاريخ الاستحقاق (هجري)]]<=EOMONTH(TODAY(),0),"باقي هذا الشهر",Table1[[#This Row],[تاريخ الاستحقاق (هجري)]]<=EOMONTH(TODAY(),1),"الشهر القادم",TRUE,"لاحقًا"))))} -> مكتملة
A35: 33 | B35: مراجعة تقرير د وسام | C35: التخطيط والحوكمة | D35: PM-01 | E35: إعداد ملف يوضح نقاط النقاط التأيد ونقاط الإعتراض وارساله للوزارة | F35: أفاقي | G35: مكتمل | H35: 46259 | I35: 46260 | J35: الوزارة | K35: تم الارسال على مجموعة الواتس اب | L35: =IF($H35="","",TEXT($H35,"[$-ar-EG]dddd، d mmmm yyyy")) -> الثلاثاء، 25 أغسطس 2026 | M35: =IF($I35="","",TEXT($I35,"[$-ar-EG]dddd، d mmmm yyyy")) -> الأربعاء، 26 أغسطس 2026 | N35: {=IF(Table1[[#This Row],[المهمة]]="","",IF(TRIM(Table1[[#This Row],[الحالة]])="مكتمل","مكتملة",IF(Table1[[#This Row],[تاريخ الاستحقاق (هجري)]]="","بدون تاريخ",_xlfn.IFS(Table1[[#This Row],[تاريخ الاستحقاق (هجري)]]<TODAY(),"متأخرة",Table1[[#This Row],[تاريخ الاستحقاق (هجري)]]=TODAY(),"اليوم",Table1[[#This Row],[تاريخ الاستحقاق (هجري)]]=TODAY()+1,"غدًا",Table1[[#This Row],[تاريخ الاستحقاق (هجري)]]<=TODAY()-WEEKDAY(TODAY(),2)+7,"باقي هذا الأسبوع",Table1[[#This Row],[تاريخ الاستحقاق (هجري)]]<=TODAY()-WEEKDAY(TODAY(),2)+14,"الأسبوع القادم",Table1[[#This Row],[تاريخ الاستحقاق (هجري)]]<=EOMONTH(TODAY(),0),"باقي هذا الشهر",Table1[[#This Row],[تاريخ الاستحقاق (هجري)]]<=EOMONTH(TODAY(),1),"الشهر القادم",TRUE,"لاحقًا"))))} -> مكتملة | Q35: اجتماع مبدائي غدا
A36: 34 | B36: بيانات الأبواب الرئيسية لمخيمات عرفات للموسم 1448 | C36: جاهزية المواقع والتنسيق الميداني | D36: PM-02 | E36: هل يوجد جداول تفويح و كيف يتم التفويج وتحديد ابواب الرئيسة للمخيمات بعرفات | F36: الوزارة | G36: قيد الانتظار | H36: 46260 | I36: 46288 | J36: أفاقي | K36: سيتم ارسال بيانات الأبواب الرئيسية للمخيمات من قبل م محمد منشي | L36: يوم الاربعاء | M36: سيتم مشاركة البيانت للموسم 1447
A37: 35 | B37: التواصل مع فريق تحليل البيانات د/حاتم (داش بورد) | C37: التخطيط والحوكمة | D37: PM-01 | E37: مناقشة تحديات الخاصة بال dashboared للموسم السابق | F37: الوزارة | G37: قيد الانتظار | H37: 46260 | I37: 46264 | J37: علم
A38: 36 | B38: التواصل مع فريق تحليل البيانات د/ حاتم (البنية الرقمية و متطلباتها) | C38: التخطيط والحوكمة | D38: PM-01 | E38: مناقشة طلبات الموسم القادم | F38: الوزارة | G38: قيد الانتظار | H38: 46260 | I38: 46264 | J38: علم | P38: خلال هذا الاسبوع | Q38: خلال الاسبوع القادم
A39: 37 | B39: مراجعة ملف الدراسة الإستضاحية للمنصة | C39: التخطيط والحوكمة | D39: PM-01 | E39: سيتم مراجعتها من قبل م احمد | F39: علم | G39: مكتمل | H39: 46261 | I39: 46264 | J39: علم
A40: 38 | B40: إنشاء ملف BRD مبدأي | C40: التخطيط والحوكمة | D40: PM-01 | E40: تجهيز ملف يوضح التصور الكامل لمتطلبات المشروع | F40: أفاقي | G40: مكتمل | H40: 46264 | I40: 46268 | J40: الوزارة
...

Sheet Dashboard
A1: لوحة متابعة المهام
A2: ="اليوم: "&TEXT(TODAY(),"[$-060401]dddd، d mmmm yyyy")&" هـ | "&TEXT(TODAY(),"[$-ar-EG]dddd، d mmmm yyyy")&" م" -> اليوم: الثلاثاء، 3 ربيع الثاني 1448 هـ | الثلاثاء، 15 سبتمبر 2026 م
A3: المؤشرات العامة
A4: إجمالي المهام | C4: المهام المكتملة | E4: قيد التنفيذ / الانتظار | G4: متأخرة عن الاستحقاق
A5: =COUNTA(Sheet2!$B$3:$B$501) -> 48 | C5: =COUNTIF(Sheet2!$G:$G,"مكتمل*") -> 24 | E5: =$A$5-$C$5 -> 24 | G5: =COUNTIFS(Sheet2!$I:$I,"<"&TODAY(),Sheet2!$I:$I,">0",Sheet2!$G:$G,"<>مكتمل*") -> 12
A7: مؤشرات الاستحقاق القريب — لا تشمل المهام المكتملة
A8: مستحق اليوم | C8: مستحق غدًا | E8: باقي هذا الأسبوع | G8: الأسبوع القادم
A9: =COUNTIFS(Sheet2!$I$3:$I$26,TODAY(),Sheet2!$G$3:$G$26,"<>مكتمل*") -> 1 | C9: =COUNTIFS(Sheet2!$I$3:$I$26,TODAY()+1,Sheet2!$G$3:$G$26,"<>مكتمل*") -> 0 | E9: =COUNTIFS(Sheet2!$I$3:$I$26,">="&TODAY(),Sheet2!$I$3:$I$26,"<="&TODAY()-WEEKDAY(TODAY(),2)+7,Sheet2!$G$3:$G$26,"<>مكتمل*") -> 1 | G9: =COUNTIFS(Sheet2!$I$3:$I$26,">="&TODAY()-WEEKDAY(TODAY(),2)+8,Sheet2!$I$3:$I$26,"<="&TODAY()-WEEKDAY(TODAY(),2)+14,Sheet2!$G$3:$G$26,"<>مكتمل*") -> 0
A11: مؤشرات الاستحقاق الأبعد — لا تشمل المهام المكتملة
A12: باقي هذا الشهر | C12: الشهر القادم | E12: ما بعد الشهر القادم | G12: بدون تاريخ استحقاق
A13: =COUNTIFS(Sheet2!$I$3:$I$26,">="&TODAY(),Sheet2!$I$3:$I$26,"<="&EOMONTH(TODAY(),0),Sheet2!$G$3:$G$26,"<>مكتمل*") -> 2 | C13: =COUNTIFS(Sheet2!$I$3:$I$26,">="&EOMONTH(TODAY(),0)+1,Sheet2!$I$3:$I$26,"<="&EOMONTH(TODAY(),1),Sheet2!$G$3:$G$26,"<>مكتمل*") -> 2 | E13: =COUNTIFS(Sheet2!$I$3:$I$26,">"&EOMONTH(TODAY(),1),Sheet2!$G$3:$G$26,"<>مكتمل*") -> 0 | G13: =COUNTIFS(Sheet2!$B$3:$B$26,"<>",Sheet2!$I$3:$I$26,"",Sheet2!$G$3:$G$26,"<>مكتمل*") -> 0
A16: نسبة الإنجاز | C16: =IF($A$5=0,0,$C$5/$A$5) -> 0.5
A18: توزيع المهام حسب الحالة
A19: الحالة | B19: العدد | C19: النسبة
A20: {=_xlfn._xlws.SORT(_xlfn.UNIQUE(_xlfn._xlws.FILTER(TRIM(Sheet2!$G$3:$G$26),Sheet2!$G$3:$G$26<>"")))} -> جاري العمل | B20: {=COUNTIF(Sheet2!$G$3:$G$26,_xlfn.ANCHORARRAY($A$20))} -> 1 | C20: {=IF($A$5=0,0,_xlfn.ANCHORARRAY($B$20)/$A$5)} -> 0.020833333
A21: قيد الانتظار | B21: 8 | C21: 0.16666667
A22: قيد التنفيذ | B22: 1 | C22: 0.020833333
A23: مكتمل | B23: 14 | C23: 0.29166667
A28: بطاقات الجهات — المهمة المشتركة تُحتسب لكل جهة مشاركة فيها
A29: أفاقي | G29: ="إجمالي المهام: "&COUNTIF(Sheet2!$F$3:$F$26,"*"&$A29&"*") -> إجمالي المهام: 17
A30: مهام مكتملة | C30: تنتهي هذا الأسبوع | E30: تنتهى خلال الشهر | G30: متأخرة عن الاستحقاق
A31: =COUNTIFS(Sheet2!$F$3:$F$26,"*"&$A$29&"*",Sheet2!$G$3:$G$26,"مكتمل*") -> 11 | C31: =COUNTIFS(Sheet2!$F$3:$F$26,"*"&$A$29&"*",Sheet2!$G$3:$G$26,"<>مكتمل*",Sheet2!$I$3:$I$26,">="&TODAY(),Sheet2!$I$3:$I$26,"<="&TODAY()-WEEKDAY(TODAY(),2)+7) -> 0 | E31: =COUNTIFS(Sheet2!$F$3:$F$26,"*"&$A$29&"*",Sheet2!$G$3:$G$26,"<>مكتمل*",Sheet2!$I$3:$I$26,">="&EOMONTH(TODAY(),0)+1,Sheet2!$I$3:$I$26,"<="&EOMONTH(TODAY(),1)) -> 2 | G31: =COUNTIFS(Sheet2!$F$3:$F$26,"*"&$A$29&"*",Sheet2!$G$3:$G$26,"<>مكتمل*",Sheet2!$I$3:$I$26,"<"&TODAY(),Sheet2!$I$3:$I$26,">0") -> 3
A34: الوزارة | G34: ="إجمالي المهام: "&COUNTIF(Sheet2!$F$3:$F$26,"*"&$A34&"*") -> إجمالي المهام: 9
A35: مهام مكتملة | C35: تنتهي هذا الأسبوع | E35: تنتهى خلال الشهر | G35: متأخرة عن الاستحقاق
A36: =COUNTIFS(Sheet2!$F$3:$F$26,"*"&$A$34&"*",Sheet2!$G$3:$G$26,"مكتمل*") -> 5 | C36: =COUNTIFS(Sheet2!$F$3:$F$26,"*"&$A$34&"*",Sheet2!$G$3:$G$26,"<>مكتمل*",Sheet2!$I$3:$I$26,">="&TODAY(),Sheet2!$I$3:$I$26,"<="&TODAY()-WEEKDAY(TODAY(),2)+7) -> 1 | E36: =COUNTIFS(Sheet2!$F$3:$F$26,"*"&$A$34&"*",Sheet2!$G$3:$G$26,"<>مكتمل*",Sheet2!$I$3:$I$26,">="&EOMONTH(TODAY(),0)+1,Sheet2!$I$3:$I$26,"<="&EOMONTH(TODAY(),1)) -> 0 | G36: =COUNTIFS(Sheet2!$F$3:$F$26,"*"&$A$34&"*",Sheet2!$G$3:$G$26,"<>مكتمل*",Sheet2!$I$3:$I$26,"<"&TODAY(),Sheet2!$I$3:$I$26,">0") -> 3
A39: علم | G39: ="إجمالي المهام: "&COUNTIF(Sheet2!$F$3:$F$26,"*"&$A39&"*") -> إجمالي المهام: 0
A40: مهام مكتملة | C40: تنتهي هذا الأسبوع | E40: تنتهى خلال الشهر | G40: متأخرة عن الاستحقاق
A41: =COUNTIFS(Sheet2!$F$3:$F$26,"*"&$A$39&"*",Sheet2!$G$3:$G$26,"مكتمل*") -> 0 | C41: =COUNTIFS(Sheet2!$F$3:$F$26,"*"&$A$39&"*",Sheet2!$G$3:$G$26,"<>مكتمل*",Sheet2!$I$3:$I$26,">="&TODAY(),Sheet2!$I$3:$I$26,"<="&TODAY()-WEEKDAY(TODAY(),2)+7) -> 0 | E41: =COUNTIFS(Sheet2!$F$3:$F$26,"*"&$A$39&"*",Sheet2!$G$3:$G$26,"<>مكتمل*",Sheet2!$I$3:$I$26,">="&EOMONTH(TODAY(),0)+1,Sheet2!$I$3:$I$26,"<="&EOMONTH(TODAY(),1)) -> 0 | G41: =COUNTIFS(Sheet2!$F$3:$F$26,"*"&$A$39&"*",Sheet2!$G$3:$G$26,"<>مكتمل*",Sheet2!$I$3:$I$26,"<"&TODAY(),Sheet2!$I$3:$I$26,">0") -> 0
